<?xml version="1.0" ?>
<!-- =================================================================================== -->
<!-- |    This document was autogenerated by xacro from src/smart_car/urdf/smartcar.urdf.xacro | -->
<!-- |    EDITING THIS FILE BY HAND IS NOT RECOMMENDED                                 | -->
<!-- =================================================================================== -->
<robot name="smartcar">
  <!--Body-->
  <link name="base_link">

  </link>
  <link name="chassis_link">
    <inertial>
      <mass value="1.0"/>
      <inertia ixx="0.01" ixy="0.0" ixz="0.0" iyy="0.01" iyz="0.0" izz="0.02"/>
      <origin xyz="0 0 1"/>
    </inertial>
    <visual>
      <geometry>
        <box size="0.17 0.257  0.01"/>
      </geometry>
    </visual>
  </link>
  <joint name="chassis_joint" type="fixed">
    <parent link="base_link"/>
    <child link="chassis_link"/>
    <origin xyz="0 0 0.032"/>
  </joint>
  <link name="front_left_wheel">
    <inertial>
      <mass value="0.2"/>
      <inertia ixx="0.0001" ixy="0.0" ixz="0.0" iyy="0.0001" iyz="0.0" izz="0.0002"/>
      <origin xyz="0 0 0"/>
    </inertial>
    <visual>
      <geometry>
        <cylinder length="0.025" radius="0.032"/>
      </geometry>
    </visual>
    <collision>
      <origin rpy="0 0 0" xyz="0 0 0"/>
      <geometry>
        <cylinder length="0.025" radius="0.032"/>
      </geometry>
    </collision>
  </link>
  <joint name="front_left_wheel_joint" type="continuous">
    <parent link="base_link"/>
    <child link="front_left_wheel"/>
    <origin rpy="0 1.5707963267948966 0" xyz="0.11000000000000001 -0.1285 0.032"/>
  </joint>
  <link name="front_right_wheel">
    <inertial>
      <mass value="0.2"/>
      <inertia ixx="0.0001" ixy="0.0" ixz="0.0" iyy="0.0001" iyz="0.0" izz="0.0002"/>
      <origin xyz="0 0 0"/>
    </inertial>
    <visual>
      <geometry>
        <cylinder length="0.025" radius="0.032"/>
      </geometry>
    </visual>
    <collision>
      <origin rpy="0 0 0" xyz="0 0 0"/>
      <geometry>
        <cylinder length="0.025" radius="0.032"/>
      </geometry>
    </collision>
  </link>
  <joint name="front_right_wheel_joint" type="continuous">
    <parent link="base_link"/>
    <child link="front_right_wheel"/>
    <origin rpy="0 1.5707963267948966 0" xyz="-0.11000000000000001 -0.1285 0.032"/>
  </joint>
  <link name="back_left_wheel">
    <inertial>
      <mass value="0.2"/>
      <inertia ixx="0.0001" ixy="0.0" ixz="0.0" iyy="0.0001" iyz="0.0" izz="0.0002"/>
      <origin xyz="0 0 0"/>
    </inertial>
    <visual>
      <geometry>
        <cylinder length="0.025" radius="0.032"/>
      </geometry>
    </visual>
    <collision>
      <origin rpy="0 0 0" xyz="0 0 0"/>
      <geometry>
        <cylinder length="0.025" radius="0.032"/>
      </geometry>
    </collision>
  </link>
  <joint name="back_left_wheel_joint" type="continuous">
    <parent link="base_link"/>
    <child link="back_left_wheel"/>
    <origin rpy="0 1.5707963267948966 0" xyz="0.11000000000000001 0.1285 0.032"/>
  </joint>
  <link name="back_right_wheel">
    <inertial>
      <mass value="0.2"/>
      <inertia ixx="0.0001" ixy="0.0" ixz="0.0" iyy="0.0001" iyz="0.0" izz="0.0002"/>
      <origin xyz="0 0 0"/>
    </inertial>
    <visual>
      <geometry>
        <cylinder length="0.025" radius="0.032"/>
      </geometry>
    </visual>
    <collision>
      <origin rpy="0 0 0" xyz="0 0 0"/>
      <geometry>
        <cylinder length="0.025" radius="0.032"/>
      </geometry>
    </collision>
  </link>
  <joint name="back_right_wheel_joint" type="continuous">
    <parent link="base_link"/>
    <child link="back_right_wheel"/>
    <origin rpy="0 1.5707963267948966 0" xyz="-0.11000000000000001 0.1285 0.032"/>
  </joint>
  <!--Sensors-->
  <!--IMU-->
  <link name="imu_link">
    <visual>
      <geometry>
        <box size="0.05 0.05 0.05"/>
      </geometry>
    </visual>
    <collision>
      <origin rpy="0 0 0" xyz="0 0 0"/>
      <geometry>
        <box size="0.1 0.1 0.1"/>
      </geometry>
    </collision>
    <inertial>
      <mass value="0.05"/>
      <inertia ixx="0.01" ixy="0.0" ixz="0.0" iyy="0.01" iyz="0.0" izz="0.02"/>
      <origin xyz="0 0 0"/>
    </inertial>
  </link>
  <joint name="imu_joint" type="fixed">
    <parent link="base_link"/>
    <child link="imu_link"/>
    <origin xyz="0 0 0.082"/>
  </joint>
  <gazebo reference="imu_link">
    <sensor name="imu_sensor" type="imu">
      <always_on>true</always_on>
      <update_rate>30.0</update_rate>
      <plugin filename="libgazebo_ros_imu.so" name="gazebo_ros_imu">
        <ros>
          <namespace>/imu</namespace>
          <remapping>~/out:=/imu/data</remapping>
        </ros>
      </plugin>
    </sensor>
  </gazebo>
  <!-- LiDAR -->
  <link name="sllidar_base_link">
    <visual>
      <geometry>
        <cylinder length="0.1" radius="0.03"/>
      </geometry>
    </visual>
    <collision>
      <origin rpy="0 0 0" xyz="0 0 0"/>
      <geometry>
        <cylinder length="0.1" radius="0.03"/>
      </geometry>
    </collision>
    <inertial>
      <mass value="0.05"/>
      <inertia ixx="0.01" ixy="0.0" ixz="0.0" iyy="0.01" iyz="0.0" izz="0.02"/>
      <origin xyz="0 0 0"/>
    </inertial>
  </link>
  <joint name="lidar_joint" type="fixed">
    <parent link="base_link"/>
    <child link="sllidar_base_link"/>
    <origin xyz="0 0.0985 0.132"/>
  </joint>
  <gazebo reference="sllidar_base_link">
    <sensor name="lidar" type="ray">
      <pose> 0 0 0 0 0 0 </pose>
      <visualize>true</visualize>
      <update_rate>10</update_rate>
      <ray>
        <scan>
          <horizontal>
            <samples>360</samples>
            <min_angle>-3.141592653589793</min_angle>
            <max_angle>3.141592653589793</max_angle>
          </horizontal>
        </scan>
        <range>
          <min>0.3</min>
          <max>12</max>
        </range>
      </ray>
      <plugin filename="libgazebo_ros_ray_sensor.so" name="lidar_plugin">
        <ros>
          <argument>~/out:=scan</argument>
        </ros>
        <output_type>sensor_msgs/LaserScan</output_type>
        <frame_name>sllidar_base_link</frame_name>
      </plugin>
    </sensor>
  </gazebo>
  <gazebo>
    <plugin filename="libcar_gazebo_plugin.so" name="car_gazebo_plugin"/>
  </gazebo>
</robot>
