<?xml version="1.0" ?>
<!-- =================================================================================== -->
<!-- |    This document was autogenerated by xacro from src/smart_car/urdf/smartcar.urdf.xacro | -->
<!-- |    EDITING THIS FILE BY HAND IS NOT RECOMMENDED                                 | -->
<!-- =================================================================================== -->
<robot name="smartcar">
  <!--Body-->
  <link name="base_link">

  </link>
  <link name="chassis_link">
    <inertial>
      <mass value="1.0"/>
      <inertia ixx="0.01" ixy="0.0" ixz="0.0" iyy="0.01" iyz="0.0" izz="0.02"/>
      <origin xyz="0 0 0"/>
    </inertial>
    <visual>
      <geometry>
        <box size="0.17 0.257  0.01"/>
      </geometry>
    </visual>
  </link>
  <joint name="chassis_joint" type="fixed">
    <parent link="base_link"/>
    <child link="chassis_link"/>
    <origin xyz="0 0 0.032"/>
  </joint>
  <link name="front_left_wheel">
    <inertial>
      <mass value="0.2"/>
      <inertia ixx="0.0001" ixy="0.0" ixz="0.0" iyy="0.0001" iyz="0.0" izz="0.0002"/>
      <origin xyz="0 0 0"/>
    </inertial>
    <visual>
      <geometry>
        <cylinder length="0.025" radius="0.032"/>
      </geometry>
    </visual>
  </link>
  <joint name="front_left_wheel_joint" type="continuous">
    <parent link="base_link"/>
    <child link="front_left_wheel"/>
    <origin rpy="0 1.5707963267948966 0" xyz="0.11000000000000001 -0.1285 0.032"/>
  </joint>
  <link name="front_right_wheel">
    <inertial>
      <mass value="0.2"/>
      <inertia ixx="0.0001" ixy="0.0" ixz="0.0" iyy="0.0001" iyz="0.0" izz="0.0002"/>
      <origin xyz="0 0 0"/>
    </inertial>
    <visual>
      <geometry>
        <cylinder length="0.025" radius="0.032"/>
      </geometry>
    </visual>
  </link>
  <joint name="front_right_wheel_joint" type="continuous">
    <parent link="base_link"/>
    <child link="front_right_wheel"/>
    <origin rpy="0 1.5707963267948966 0" xyz="-0.11000000000000001 -0.1285 0.032"/>
  </joint>
  <link name="back_left_wheel">
    <inertial>
      <mass value="0.2"/>
      <inertia ixx="0.0001" ixy="0.0" ixz="0.0" iyy="0.0001" iyz="0.0" izz="0.0002"/>
      <origin xyz="0 0 0"/>
    </inertial>
    <visual>
      <geometry>
        <cylinder length="0.025" radius="0.032"/>
      </geometry>
    </visual>
  </link>
  <joint name="back_left_wheel_joint" type="continuous">
    <parent link="base_link"/>
    <child link="back_left_wheel"/>
    <origin rpy="0 1.5707963267948966 0" xyz="0.11000000000000001 0.1285 0.032"/>
  </joint>
  <link name="back_right_wheel">
    <inertial>
      <mass value="0.2"/>
      <inertia ixx="0.0001" ixy="0.0" ixz="0.0" iyy="0.0001" iyz="0.0" izz="0.0002"/>
      <origin xyz="0 0 0"/>
    </inertial>
    <visual>
      <geometry>
        <cylinder length="0.025" radius="0.032"/>
      </geometry>
    </visual>
  </link>
  <joint name="back_right_wheel_joint" type="continuous">
    <parent link="base_link"/>
    <child link="back_right_wheel"/>
    <origin rpy="0 1.5707963267948966 0" xyz="-0.11000000000000001 0.1285 0.032"/>
  </joint>
  <!--Sensors-->
  <!--IMU-->
  <!-- <link name="imu_link">
    <sensor name="imu_sensor" type="imu">
      <always_on>true</always_on> -->
  <!-- Publish at 30 hz -->
  <!-- <update_rate>30</update_rate>
      <plugin name="gazebo_ros_imu_sensor" filename="libgazebo_ros_imu_sensor.so">
        <ros> -->
  <!-- Will publish to /imu/data -->
  <!-- <namespace>/imu</namespace>
          <remapping>~/out:=data</remapping>
        </ros>
      </plugin>
    </sensor>
  </link>

  <joint name="imu_joint" type="fixed">
    <parent link="base_link" />
    <child link="imu_link"/>
    <origin xyz="0 0 ${wheel_diameter / 2}"/>
  </joint> -->
  <!-- LiDAR -->
  <!-- <link name="sllidar_base_link"> -->
  <!-- TODO: add visual for LiDAR -->
  <!-- </link>

  <joint name="lidar_joint" type="fixed">
    <parent link="base_link" />
    <child link="sllidar_base_link"/>
    <origin xyz="0 0 ${wheel_diameter / 2}"/>
  </joint>

  <gazebo reference="sllidar_base_link">
    <sensor type="ray" name="lidar_sensor">
      <update_rate>30.0</update_rate>
      <plugin name="gazebo_ros_ray_sensor" filename="libgazebo_ros_ray_sensor.so">
        <topic>/scan</topic> 
        <frameName>sllidar_base_link</frameName> 
      </plugin>
    </sensor>
  </gazebo> -->
</robot>
